<?xml version="1.0" encoding="utf-8"?>
<!-- This URDF was automatically created by SolidWorks to URDF Exporter! Originally created by Stephen Brawner (brawner@gmail.com) 
     Commit Version: 1.6.0-4-g7f85cfe  Build Version: 1.6.7995.38578
     For more information, please see http://wiki.ros.org/sw_urdf_exporter -->
<robot
  name="cr_no_v.SLDASM">
  <link
    name="base_link">
    <inertial>
      <origin
        xyz="0.00351046096422747 9.38533445404843E-07 0.202333863971419"
        rpy="0 0 0" />
      <mass
        value="50.0462632224717" />
      <inertia
        ixx="2.77166621279028"
        ixy="2.01422969466445E-07"
        ixz="-0.0536875907875239"
        iyy="2.83719349623548"
        iyz="-5.35660563253282E-05"
        izz="2.69143233661378" />
    </inertial>
    <visual>
      <origin
        xyz="0 0 0"
        rpy="0 0 0" />
      <geometry>
        <mesh
          filename="package://cr_no_v.SLDASM/meshes/base_link.STL" />
      </geometry>
      <material
        name="al">
        <color
          rgba="0 0.6 1 1" />
      </material>
    </visual>
    <collision>
      <origin
        xyz="0 0 0"
        rpy="0 0 0" />
      <geometry>
        <mesh
          filename="package://cr_no_v.SLDASM/meshes/base_link.STL" />
      </geometry>
    </collision>
  </link>
  <link
    name="wheel_rf_link">
    <inertial>
      <origin
        xyz="-2.377E-08 0.025001 -6.6441E-06"
        rpy="0 0 0" />
      <mass
        value="1.6415" />
      <inertia
        ixx="0.005947"
        ixy="1.8204E-10"
        ixz="-1.3982E-09"
        iyy="0.011256"
        iyz="-3.3293E-10"
        izz="0.005947" />
    </inertial>
    <visual>
      <origin
        xyz="0 0 0"
        rpy="0 0 0" />
      <geometry>
        <mesh
          filename="package://cr_no_v.SLDASM/meshes/wheel_rf_link.STL" />
      </geometry>
      <material
        name="">
        <color
          rgba="0.5451 0.52549 0.41961 1" />
      </material>
    </visual>
    <collision>
      <origin
        xyz="0 0 0"
        rpy="0 0 0" />
      <geometry>
        <mesh
          filename="package://cr_no_v.SLDASM/meshes/wheel_rf_link.STL" />
      </geometry>
    </collision>
  </link>
  <joint
    name="wheel_rf_joint"
    type="continuous">
    <origin
      xyz="0.1787 -0.32914 0.1125"
      rpy="0 0 0" />
    <parent
      link="base_link" />
    <child
      link="wheel_rf_link" />
    <axis
      xyz="0 1 0" />
  </joint>
  <link
    name="wheel_lf_link">
    <inertial>
      <origin
        xyz="6.1889E-08 -0.024999 -3.4683E-06"
        rpy="0 0 0" />
      <mass
        value="1.6415" />
      <inertia
        ixx="0.005947"
        ixy="3.0662E-11"
        ixz="1.9576E-09"
        iyy="0.011256"
        iyz="-3.3292E-10"
        izz="0.005947" />
    </inertial>
    <visual>
      <origin
        xyz="0 0 0"
        rpy="0 0 0" />
      <geometry>
        <mesh
          filename="package://cr_no_v.SLDASM/meshes/wheel_lf_link.STL" />
      </geometry>
      <material
        name="">
        <color
          rgba="0.5451 0.52549 0.41961 1" />
      </material>
    </visual>
    <collision>
      <origin
        xyz="0 0 0"
        rpy="0 0 0" />
      <geometry>
        <mesh
          filename="package://cr_no_v.SLDASM/meshes/wheel_lf_link.STL" />
      </geometry>
    </collision>
  </link>
  <joint
    name="wheel_lf_joint"
    type="continuous">
    <origin
      xyz="0.1787 0.32914 0.1125"
      rpy="0 0 0" />
    <parent
      link="base_link" />
    <child
      link="wheel_lf_link" />
    <axis
      xyz="0 1 0" />
  </joint>
  <link
    name="wheel_lr_link">
    <inertial>
      <origin
        xyz="0.00013107 1.5985E-06 0.020265"
        rpy="0 0 0" />
      <mass
        value="1.6024" />
      <inertia
        ixx="0.0057413"
        ixy="1.4654E-34"
        ixz="1.2543E-19"
        iyy="0.0057413"
        iyz="-7.5792E-18"
        izz="0.010787" />
    </inertial>
    <visual>
      <origin
        xyz="0 0 0"
        rpy="0 0 0" />
      <geometry>
        <mesh
          filename="package://cr_no_v.SLDASM/meshes/wheel_lr_link.STL" />
      </geometry>
      <material
        name="">
        <color
          rgba="0.5451 0.52549 0.41961 1" />
      </material>
    </visual>
    <collision>
      <origin
        xyz="0 0 0"
        rpy="0 0 0" />
      <geometry>
        <mesh
          filename="package://cr_no_v.SLDASM/meshes/wheel_lr_link.STL" />
      </geometry>
    </collision>
  </link>
  <joint
    name="wheel_lr_joint"
    type="continuous">
    <origin
      xyz="-0.17499 0.3244 0.1125"
      rpy="1.5708 0 0" />
    <parent
      link="base_link" />
    <child
      link="wheel_lr_link" />
    <axis
      xyz="-0.0003518 0 -1" />
  </joint>
  <link
    name="wheel_rr_Link">
    <inertial>
      <origin
        xyz="-9.7179E-05 0.020265 -2.9986E-09"
        rpy="0 0 0" />
      <mass
        value="1.6024" />
      <inertia
        ixx="0.0057413"
        ixy="-1.4123E-19"
        ixz="4.9644E-34"
        iyy="0.010787"
        iyz="-1.7435E-17"
        izz="0.0057413" />
    </inertial>
    <visual>
      <origin
        xyz="0 0 0"
        rpy="0 0 0" />
      <geometry>
        <mesh
          filename="package://cr_no_v.SLDASM/meshes/wheel_rr_Link.STL" />
      </geometry>
      <material
        name="">
        <color
          rgba="0.5451 0.52549 0.41961 1" />
      </material>
    </visual>
    <collision>
      <origin
        xyz="0 0 0"
        rpy="0 0 0" />
      <geometry>
        <mesh
          filename="package://cr_no_v.SLDASM/meshes/wheel_rr_Link.STL" />
      </geometry>
    </collision>
  </link>
  <joint
    name="wheel_rr_joint"
    type="continuous">
    <origin
      xyz="-0.17476 -0.3244 0.1125"
      rpy="0 0 0" />
    <parent
      link="base_link" />
    <child
      link="wheel_rr_Link" />
    <axis
      xyz="-0.0003518 1 0" />
  </joint>
  <link
    name="Rob_base">
    <inertial>
      <origin
        xyz="0.00061297 0.00059199 0.039398"
        rpy="0 0 0" />
      <mass
        value="0.91605" />
      <inertia
        ixx="0.0013992"
        ixy="1.6838E-07"
        ixz="1.1024E-07"
        iyy="0.0013771"
        iyz="1.2662E-06"
        izz="0.0016573" />
    </inertial>
    <visual>
      <origin
        xyz="0 0 0"
        rpy="0 0 0" />
      <geometry>
        <mesh
          filename="package://cr_no_v.SLDASM/meshes/Rob_base.STL" />
      </geometry>
      <material
        name="">
        <color
          rgba="0.6 0.6 0.6 1" />
      </material>
    </visual>
    <collision>
      <origin
        xyz="0 0 0"
        rpy="0 0 0" />
      <geometry>
        <mesh
          filename="package://cr_no_v.SLDASM/meshes/Rob_base.STL" />
      </geometry>
    </collision>
  </link>
  <joint
    name="Rob_base_fix"
    type="fixed">
    <origin
      xyz="0.15995 0 0.9465"
      rpy="-1.5708 0 -1.5708" />
    <parent
      link="base_link" />
    <child
      link="Rob_base" />
    <axis
      xyz="0 0 0" />
  </joint>
  <link
    name="arm_seg1">
    <inertial>
      <origin
        xyz="8.9128E-09 -0.00016808 0.057416"
        rpy="0 0 0" />
      <mass
        value="0.55857" />
      <inertia
        ixx="0.00064447"
        ixy="-8.2983E-11"
        ixz="9.7825E-11"
        iyy="0.00075757"
        iyz="-1.0039E-06"
        izz="0.00052009" />
    </inertial>
    <visual>
      <origin
        xyz="0 0 0"
        rpy="0 0 0" />
      <geometry>
        <mesh
          filename="package://cr_no_v.SLDASM/meshes/arm_seg1.STL" />
      </geometry>
      <material
        name="">
        <color
          rgba="0.6 0.6 0.6 1" />
      </material>
    </visual>
    <collision>
      <origin
        xyz="0 0 0"
        rpy="0 0 0" />
      <geometry>
        <mesh
          filename="package://cr_no_v.SLDASM/meshes/arm_seg1.STL" />
      </geometry>
    </collision>
  </link>
  <joint
    name="arm_seg1_rev"
    type="revolute">
    <origin
      xyz="0 0 0.0892"
      rpy="0 0 1.5708" />
    <parent
      link="Rob_base" />
    <child
      link="arm_seg1" />
    <axis
      xyz="0 0 -1" />
    <limit
      lower="0"
      upper="0"
      effort="0"
      velocity="0" />
  </joint>
  <link
    name="arm_seg2">
    <inertial>
      <origin
        xyz="0.20298 0.018509 0.00037949"
        rpy="0 0 0" />
      <mass
        value="0.76675" />
      <inertia
        ixx="0.001099"
        ixy="-0.00066885"
        ixz="2.1104E-05"
        iyy="0.014608"
        iyz="-2.2639E-07"
        izz="0.014433" />
    </inertial>
    <visual>
      <origin
        xyz="0 0 0"
        rpy="0 0 0" />
      <geometry>
        <mesh
          filename="package://cr_no_v.SLDASM/meshes/arm_seg2.STL" />
      </geometry>
      <material
        name="">
        <color
          rgba="0.61176 0.65882 0.67059 1" />
      </material>
    </visual>
    <collision>
      <origin
        xyz="0 0 0"
        rpy="0 0 0" />
      <geometry>
        <mesh
          filename="package://cr_no_v.SLDASM/meshes/arm_seg2.STL" />
      </geometry>
    </collision>
  </link>
  <joint
    name="arm_seg2_rev"
    type="revolute">
    <origin
      xyz="0 0 0.0615"
      rpy="1.5708 0 0" />
    <parent
      link="arm_seg1" />
    <child
      link="arm_seg2" />
    <axis
      xyz="0 0 1" />
    <limit
      lower="0"
      upper="0"
      effort="0"
      velocity="0" />
  </joint>
  <link
    name="arm_seg3">
    <inertial>
      <origin
        xyz="0.062638 0.099583 -0.00060821"
        rpy="0 0 0" />
      <mass
        value="0.92519" />
      <inertia
        ixx="0.0054137"
        ixy="-0.0005461"
        ixz="9.1776E-09"
        iyy="0.00089221"
        iyz="1.2056E-11"
        izz="0.0054963" />
    </inertial>
    <visual>
      <origin
        xyz="0 0 0"
        rpy="0 0 0" />
      <geometry>
        <mesh
          filename="package://cr_no_v.SLDASM/meshes/arm_seg3.STL" />
      </geometry>
      <material
        name="">
        <color
          rgba="0.61176 0.65882 0.67059 1" />
      </material>
    </visual>
    <collision>
      <origin
        xyz="0 0 0"
        rpy="0 0 0" />
      <geometry>
        <mesh
          filename="package://cr_no_v.SLDASM/meshes/arm_seg3.STL" />
      </geometry>
    </collision>
  </link>
  <joint
    name="arm_seg3_rev"
    type="revolute">
    <origin
      xyz="0.34928 0.02 -0.00068495"
      rpy="-3.1416 0 1.5708" />
    <parent
      link="arm_seg2" />
    <child
      link="arm_seg3" />
    <axis
      xyz="0 0 1" />
    <limit
      lower="0"
      upper="0"
      effort="0"
      velocity="0" />
  </joint>
  <link
    name="arm_seg4">
    <inertial>
      <origin
        xyz="0.00060866 -0.0011863 0.27449"
        rpy="0 0 0" />
      <mass
        value="0.082693" />
      <inertia
        ixx="6.2751E-05"
        ixy="-1.3077E-09"
        ixz="7.6011E-10"
        iyy="7.2735E-05"
        iyz="3.0814E-06"
        izz="5.9938E-05" />
    </inertial>
    <visual>
      <origin
        xyz="0 0 0"
        rpy="0 0 0" />
      <geometry>
        <mesh
          filename="package://cr_no_v.SLDASM/meshes/arm_seg4.STL" />
      </geometry>
      <material
        name="">
        <color
          rgba="0.6 0.6 0.6 1" />
      </material>
    </visual>
    <collision>
      <origin
        xyz="0 0 0"
        rpy="0 0 0" />
      <geometry>
        <mesh
          filename="package://cr_no_v.SLDASM/meshes/arm_seg4.STL" />
      </geometry>
    </collision>
  </link>
  <joint
    name="arm_seg4_rev"
    type="revolute">
    <origin
      xyz="0.07 0.00395 0"
      rpy="1.5708 1.5708 0" />
    <parent
      link="arm_seg3" />
    <child
      link="arm_seg4" />
    <axis
      xyz="0 0 -1" />
    <limit
      lower="0"
      upper="0"
      effort="0"
      velocity="0" />
  </joint>
  <link
    name="arm_seg5">
    <inertial>
      <origin
        xyz="-0.00060822 -0.05437 0.0043434"
        rpy="0 0 0" />
      <mass
        value="0.16811" />
      <inertia
        ixx="0.00012612"
        ixy="-6.1178E-11"
        ixz="-8.5675E-12"
        iyy="8.8779E-05"
        iyz="-2.0109E-05"
        izz="0.00010791" />
    </inertial>
    <visual>
      <origin
        xyz="0 0 0"
        rpy="0 0 0" />
      <geometry>
        <mesh
          filename="package://cr_no_v.SLDASM/meshes/arm_seg5.STL" />
      </geometry>
      <material
        name="">
        <color
          rgba="0.6 0.6 0.6 1" />
      </material>
    </visual>
    <collision>
      <origin
        xyz="0 0 0"
        rpy="0 0 0" />
      <geometry>
        <mesh
          filename="package://cr_no_v.SLDASM/meshes/arm_seg5.STL" />
      </geometry>
    </collision>
  </link>
  <joint
    name="arm_seg5_rev"
    type="revolute">
    <origin
      xyz="0 0 0.2776"
      rpy="-1.5708 0 3.1416" />
    <parent
      link="arm_seg4" />
    <child
      link="arm_seg5" />
    <axis
      xyz="0 0 1" />
    <limit
      lower="0"
      upper="0"
      effort="0"
      velocity="0" />
  </joint>
  <link
    name="arm_seg6">
    <inertial>
      <origin
        xyz="3.3859E-05 3.3861E-05 3.3858E-05"
        rpy="0 0 0" />
      <mass
        value="0.0005335" />
      <inertia
        ixx="5.4365E-09"
        ixy="6.1125E-13"
        ixz="6.1448E-13"
        iyy="5.4365E-09"
        iyz="6.1131E-13"
        izz="5.4365E-09" />
    </inertial>
    <visual>
      <origin
        xyz="0 0 0"
        rpy="0 0 0" />
      <geometry>
        <mesh
          filename="package://cr_no_v.SLDASM/meshes/arm_seg6.STL" />
      </geometry>
      <material
        name="">
        <color
          rgba="0.79216 0.81961 0.93333 1" />
      </material>
    </visual>
    <collision>
      <origin
        xyz="0 0 0"
        rpy="0 0 0" />
      <geometry>
        <mesh
          filename="package://cr_no_v.SLDASM/meshes/arm_seg6.STL" />
      </geometry>
    </collision>
  </link>
  <joint
    name="arm_seg6_rev"
    type="revolute">
    <origin
      xyz="0 -0.1575 0"
      rpy="1.5708 0 0" />
    <parent
      link="arm_seg5" />
    <child
      link="arm_seg6" />
    <axis
      xyz="0 0 1" />
    <limit
      lower="0"
      upper="0"
      effort="0"
      velocity="0" />
  </joint>
</robot>